Workbook

Sheet GİRDİ & PARAMETRELER
A1: 2026 YILI İŞÇİLİK ALACAKLARI HESAPLAMA ŞABLONu
A3: BİLİRKİŞİ HESAP ARACI · 01.01.2026 – 31.12.2026 Parametreleri
A5: A. İŞÇİ BİLGİLERİ (GİRDİ)
A6: Tarih Bilgileri | E6: Otomatik Hesaplanan
C7: İşe Giriş Tarihi | E7: Hizmet Süresi (Yıl) | G7: =IF(AND(ISNUMBER(D7),ISNUMBER(D8)),DATEDIF(D7,D8,"Y"),"") | H7: Yıl
C8: İşten Çıkış Tarihi | E8: Hizmet Süresi (Kalan Ay) | G8: =IF(AND(ISNUMBER(D7),ISNUMBER(D8)),DATEDIF(D7,D8,"YM"),"") | H8: Ay
C9: Kalan Gün (+1 dahil) | E9: Toplam Hizmet Günü | G9: =IF(AND(ISNUMBER(D7),ISNUMBER(D8)),DATEDIF(D7,D8,"MD")+1,"") | H9: Gün
A11: B. ÜCRET BİLGİLERİ
C12: Aylık Çıplak Brüt Ücret (TL) | D12: 0 | E12: Temel brüt maaş – ek ödemeler dahil değil
C13: Aylık Net Ücret (biliniyorsa, TL) | D13: 0 | E13: Net ücret girilmişse brüt otomatik hesaplanır
C14: Yemek Yardımı (Aylık Brüt TL) | D14: 0
C15: Yol/Servis Yardımı (Aylık Brüt TL) | D15: 0
C16: İkramiye (Aylık Brüt TL) | D16: 0 | E16: Yıllık ikramiyenin 1/12'si
C17: Prim (Aylık Brüt TL) | D17: 0
C18: Barınma/Konut (Aylık Brüt TL) | D18: 0
C19: Diğer Ayni/Nakdi Yardımlar (Aylık Brüt TL) | D19: 0
A21: C. ÜCRET HESABI (OTOMATİK)
C22: Çıplak Brüt Ücret | D22: =D12 -> 0 | E22: Girilen değer esas alınır
C23: Giydirilmiş Brüt Ücret | D23: =D12+D14+D15+D16+D17+D18+D19 -> 0 | E23: Çıplak + Tüm Yan Haklar
C24: SGK İşçi Payı (%15) | D24: =D22*0.15 -> 0
C25: İşsizlik İşçi Payı (%1) | D25: =D22*0.01 -> 0
C26: Asgari Ücret İstisnası GV (aylık) | D26: =B46 -> 0 | E26: Parametre sayfasından çekilir
C27: Asgari Ücret İstisnası DV (aylık) | D27: =B47 -> 0
A29: D. DİĞER GİRDİLER
C30: Kullanılmamış Yıllık İzin Gün Sayısı | D30: 0 | E30: gün
C31: Haftalık Ortalama Fazla Mesai Saati | D31: 0 | E31: saat/hafta
C32: Toplam Fazla Mesai Saati (tüm dönem) | D32: 0 | E32: saat (otomatik veya manuel)
C33: UBGT Çalışılan Gün Sayısı (tüm dönem) | D33: 0 | E33: gün
C34: Hakkaniyet İndirimi Oranı (FM/UBGT) | D34: 0.3 | E34: 0.30 = %30, 0 = indirim yok
C35: Kümülatif GV Matrahı (işten çıkış ayı) | D35: 0 | E35: TL - bordrodan bakılacak
C36: Toplam FM Saati (otomatik hesap) | D36: =IF(D32>0,D32,D31*IFERROR(DATEDIF(D7,D8,"d")/7,0)) -> 0 | E36: D32 boşsa D31 × toplam hafta kullanılır
A39: E. 2026 YILI SABİT PARAMETRELERİ (DEĞİŞTİRMEYİN)
C40: Asgari Ücret Brüt (01.01.2026–31.12.2026) | D40: 33030
C41: Asgari Ücret Net | D41: 28075.5
C42: Kıdem Tazminatı Tavanı (01.01.2026–30.06.2026) | D42: 64948.77
C43: SGK İşçi Payı | D43: 0.14
C44: İşsizlik İşçi Payı | D44: 0.01
C45: Damga Vergisi Oranı | D45: 0.00759
C46: Asgari Ücret GV İstisnası (aylık) | D46: 4211.33
C47: Asgari Ücret DV İstisnası (aylık) | D47: 250.7
...

Sheet KIDEM TAZMİNATI
A1: KIDEM TAZMİNATI HESABI
A3: Formül: (Giydirilmiş Brüt Ücret ≤ Tavan) × Tam Yıl + Tavan/365 × Artan Gün
A5: A. TEMEL BİLGİLER (Girdi sayfasından otomatik)
C6: İşe Giriş Tarihi | D6: ='GİRDİ & PARAMETRELER'!D7 -> 0
C7: İşten Çıkış Tarihi | D7: ='GİRDİ & PARAMETRELER'!D8 -> 0
C8: Tam Yıl | D8: ='GİRDİ & PARAMETRELER'!G7
C9: Kalan Ay | D9: ='GİRDİ & PARAMETRELER'!G8
C10: Kalan Gün (+1 dahil) | D10: ='GİRDİ & PARAMETRELER'!G9
C11: Giydirilmiş Brüt Ücret | D11: ='GİRDİ & PARAMETRELER'!D23 -> 0
C12: Kıdem Tazminatı Tavanı | D12: ='GİRDİ & PARAMETRELER'!D42 -> 64948.77
C13: Hesaplamada Esas Alınan Ücret | D13: =MIN(D11,D12) -> 0
C14: =IF(D11>D12,"⚠ DİKKAT: Giydirilmiş ücret tavanı aşıyor! Hesaplamada tavan esas alınmaktadır.","✓ Ücret tavan altında. Gerçek ücret esas alınmaktadır.") -> ✓ Ücret tavan altında. Gerçek ücret esas alınmaktadır.
A16: B. KIDEM TAZMİNATI HESABI
C17: Tam Yıl Kıdemi | D17: =IFERROR(D13*IF(ISNUMBER(D8),D8,0),0) -> 0 | E17: =
C18: Artan Gün Kıdemi | D18: =IFERROR(D13/365*IF(ISNUMBER(D10),D10,0),0) -> 0 | E18: =
C19: BRÜT KIDEM TAZMİNATI | D19: =D17+D18 -> 0 | E19: =
A21: C. KESİNTİLER
C22: Damga Vergisi (‰7,59) | D22: =D19*0.00759 -> 0 | E22: SGK ve Gelir Vergisi KESİLMEZ – Yalnızca Damga Vergisi
C23: AÜ Damga Vergisi İstisnası (maaştan kalan bakiye) | D23: =MAX(0,'GİRDİ & PARAMETRELER'!D47-'GİRDİ & PARAMETRELER'!D27) -> 250.7 | E23: İşten çıkış ayı maaşından arta kalan DV istisnası (damga vergisinden düşülür)
C24: NET DAMGA VERGİSİ (ödenmesi gereken) | D24: =MAX(0,D22-D23) -> 0
A26: D. SONUÇ
C27: BRÜT KIDEM TAZMİNATI | D27: =D19 -> 0
C28: (-) Net Damga Vergisi | D28: =-D24 -> 0
C29: NET KIDEM TAZMİNATI | D29: =D27+D28 -> 0

Sheet İHBAR TAZMİNATI
A1: İHBAR TAZMİNATI HESABI
A3: Formül: (Giydirilmiş Brüt Ücret ÷ 30) × İhbar Gün Sayısı
A5: A. KİDAM – İHBAR SÜRESİ TABLOSU
C6: Kıdem Süresi | F6: İhbar Süresi (Gün)
C7: 6 aydan az | F7: 14
C8: 6 ay – 1,5 yıl | F8: 28
C9: 1,5 yıl – 3 yıl | F9: 42
C10: 3 yıldan fazla | F10: 56
A12: B. OTOMATİK İHBAR SÜRESİ HESABI
C13: Toplam Hizmet Süresi (Yıl olarak) | D13: =IFERROR('GİRDİ & PARAMETRELER'!G7+'GİRDİ & PARAMETRELER'!G8/12+'GİRDİ & PARAMETRELER'!G9/365,0) -> 0
C14: İhbar Süresi (Otomatik Hesap – Gün) | D14: =IF(D13<0.5,14,IF(D13<1.5,28,IF(D13<3,42,56))) -> 14 | E14: Hafta: 8w=56g, 6w=42g, 4w=28g, 2w=14g
A16: C. İHBAR TAZMİNATI HESABI
C17: Giydirilmiş Brüt Ücret | D17: =IFERROR('GİRDİ & PARAMETRELER'!D23,0) -> 0
C18: Günlük Giydirilmiş Ücret | D18: =IFERROR(D17/30,0) -> 0
C19: İhbar Gün Sayısı | D19: =D14 -> 14
C20: BRÜT İHBAR TAZMİNATI | D20: =IFERROR(D18*D19,0) -> 0
A22: D. KESİNTİLER
C23: Kümülatif GV Matrahı (işten çıkış ayı) | D23: ='GİRDİ & PARAMETRELER'!D35 -> 0
C24: İhbar Brüt Tutarı (GV Matrahı) | D24: =D20 -> 0
C25: Gelir Vergisi (Kademeli – 2026) | D25: =IF('GİRDİ & PARAMETRELER'!D35+D24<=190000,D24*0.15,IF('GİRDİ & PARAMETRELER'!D35>=5300000,D24*0.4,IF('GİRDİ & PARAMETRELER'!D35>=1500000,D24*0.35,IF('GİRDİ & PARAMETRELER'!D35>=400000,D24*0.27,IF('GİRDİ & PARAMETRELER'!D35>=190000,D24*0.2,D24*0.15))))) -> 0 | E25: Kümülatif matrah esas alınarak uygulanacak dilim oranı kullanılır
C26: AÜ GV İstisnası (maaştan kalan bakiye) | D26: =MAX(0,'GİRDİ & PARAMETRELER'!D46-'GİRDİ & PARAMETRELER'!D26) -> 4211.33
C27: NET GELİR VERGİSİ (ödenmesi gereken) | D27: =MAX(0,D25-D26) -> 0
C28: Damga Vergisi (‰7,59) | D28: =D20*0.00759 -> 0
C29: AÜ DV İstisnası (maaştan kalan bakiye) | D29: =MAX(0,'GİRDİ & PARAMETRELER'!D47-'GİRDİ & PARAMETRELER'!D27) -> 250.7
C30: NET DAMGA VERGİSİ | D30: =MAX(0,D28-D29) -> 0
A32: E. SONUÇ
C33: BRÜT İHBAR TAZMİNATI | D33: =D20 -> 0
C34: (-) Net Gelir Vergisi | D34: =-D27 -> 0
C35: (-) Net Damga Vergisi | D35: =-D30 -> 0
C36: NET İHBAR TAZMİNATI | D36: =D33+D34+D35 -> 0

Sheet YILLIK İZİN
A1: YILLIK İZİN ÜCRETİ HESABI
A3: Formül: (Çıplak Brüt Ücret ÷ 30) × Kullanılmayan İzin Gün Sayısı
A5: A. İZİN HAKKI TABLOSU
C6: Kıdem | F6: Yıllık İzin Hakkı
C7: 1 – 5 Yıl | F7: 14 Gün
C8: 5 – 15 Yıl | F8: 20 Gün
C9: 15+ Yıl | F9: 26 Gün
C10: 18 yaş altı / 50 yaş üstü | F10: Min. 20 Gün
C11: Yeraltı işçisi | F11: +4 Gün eklenir
A13: B. HESAPLAMA
C14: Çıplak Brüt Ücret | D14: ='GİRDİ & PARAMETRELER'!D22 -> 0
C15: Günlük Çıplak Ücret | D15: =D14/30 -> 0
C16: Toplam Hizmet Yılı | D16: ='GİRDİ & PARAMETRELER'!G7
C17: Yıllık İzin Hakkı (Günü) | D17: =IF(D16<5,14,IF(D16<15,20,26)) -> 26
C18: Kullanılmamış İzin Günü | D18: ='GİRDİ & PARAMETRELER'!D30 -> 0
C19: BRÜT YILLIK İZİN ÜCRETİ | D19: =D15*D18 -> 0
A21: C. KESİNTİLER
C22: SGK İşçi Payı (%14) | D22: =D19*0.14 -> 0
C23: İşsizlik İşçi Payı (%1) | D23: =D19*0.01 -> 0
C24: GV Matrahı (Brüt - SGK - İşsizlik) | D24: =D19-D22-D23 -> 0
C25: Gelir Vergisi (Kademeli) | D25: =IF('GİRDİ & PARAMETRELER'!D35+D24<=190000,D24*0.15,IF('GİRDİ & PARAMETRELER'!D35>=5300000,D24*0.4,IF('GİRDİ & PARAMETRELER'!D35>=1500000,D24*0.35,IF('GİRDİ & PARAMETRELER'!D35>=400000,D24*0.27,IF('GİRDİ & PARAMETRELER'!D35>=190000,D24*0.2,D24*0.15))))) -> 0
C26: AÜ GV İstisnası (maaştan kalan) | D26: =MAX(0,'GİRDİ & PARAMETRELER'!D46-'GİRDİ & PARAMETRELER'!D26) -> 4211.33
C27: NET Gelir Vergisi | D27: =MAX(0,D25-D26) -> 0
C28: Damga Vergisi (‰7,59) | D28: =D19*0.00759 -> 0
C29: AÜ DV İstisnası (maaştan kalan) | D29: =MAX(0,'GİRDİ & PARAMETRELER'!D47-'GİRDİ & PARAMETRELER'!D27) -> 250.7
C30: NET Damga Vergisi | D30: =MAX(0,D28-D29) -> 0
C31: TOPLAM KESİNTİ | D31: =D22+D23+D27+D30 -> 0
A33: D. SONUÇ
C34: BRÜT YILLIK İZİN ÜCRETİ | D34: =D19 -> 0
C35: (-) Toplam Kesinti | D35: =-D31 -> 0
C36: NET YILLIK İZİN ÜCRETİ | D36: =D34+D35 -> 0

Sheet FAZLA MESAİ & UBGT
A1: FAZLA MESAİ & UBGT ÜCRETİ HESABI
A3: FM: (Çıplak Brüt ÷ 225) × 1.5 × FM Saati | UBGT: (Çıplak Brüt ÷ 30) × Gün
A5: A. FAZLA MESAİ ÜCRETİ
C6: Çıplak Brüt Ücret | D6: ='GİRDİ & PARAMETRELER'!D22 -> 0
C7: Saatlik Çıplak Ücret (÷225) | D7: =D6/225 -> 0
C8: Fazla Mesai Zam Katsayısı | D8: 1.5
C9: Toplam Fazla Mesai Saati | D9: ='GİRDİ & PARAMETRELER'!D36 -> 0
C10: BRÜT FM ÜCRETİ (Tavan öncesi) | D10: =D7*D8*D9 -> 0
C11: Hakkaniyet İndirimi Oranı | D11: ='GİRDİ & PARAMETRELER'!D34 -> 0.3
C12: Hakkaniyet Sonrası BRÜT FM | D12: =D10*(1-D11) -> 0
C13: NOT: Fazla mesai salt tanık beyanıyla ispatlanıyorsa hakkaniyet indirimi %30 uygulanır.
A14: A.2 FM KESİNTİLER
C15: SGK İşçi Payı (%14) | D15: =D12*0.14 -> 0
C16: İşsizlik İşçi Payı (%1) | D16: =D12*0.01 -> 0
C17: GV Matrahı | D17: =D12-D15-D16 -> 0
C18: Gelir Vergisi (Kademeli) | D18: =IF('GİRDİ & PARAMETRELER'!D35+D17<=190000,D17*0.15,IF('GİRDİ & PARAMETRELER'!D35>=5300000,D17*0.4,IF('GİRDİ & PARAMETRELER'!D35>=1500000,D17*0.35,IF('GİRDİ & PARAMETRELER'!D35>=400000,D17*0.27,IF('GİRDİ & PARAMETRELER'!D35>=190000,D17*0.2,D17*0.15))))) -> 0
C19: Damga Vergisi (‰7,59) | D19: =D12*0.00759 -> 0
C20: TOPLAM KESİNTİ | D20: =D15+D16+D18+D19 -> 0
C21: NET FAZLA MESAİ ÜCRETİ | D21: =D12-D20 -> 0
A24: B. UBGT ÜCRETİ (Ulusal Bayram ve Genel Tatil)
C25: Çıplak Brüt Ücret | D25: ='GİRDİ & PARAMETRELER'!D22 -> 0
C26: Günlük Çıplak Ücret (÷30) | D26: =D25/30 -> 0
C27: UBGT Çalışılan Gün Sayısı | D27: ='GİRDİ & PARAMETRELER'!D33 -> 0
C28: BRÜT UBGT ÜCRETİ (Tavan öncesi) | D28: =D26*D27 -> 0
C29: Hakkaniyet İndirimi Oranı | D29: ='GİRDİ & PARAMETRELER'!D34 -> 0.3
C30: Hakkaniyet Sonrası BRÜT UBGT | D30: =D28*(1-D29) -> 0
A32: B.2 UBGT KESİNTİLER
C33: SGK İşçi Payı (%14) | D33: =D30*0.14 -> 0
C34: İşsizlik İşçi Payı (%1) | D34: =D30*0.01 -> 0
C35: GV Matrahı | D35: =D30-D33-D34 -> 0
C36: Gelir Vergisi (Kademeli) | D36: =IF('GİRDİ & PARAMETRELER'!D35+D35<=190000,D35*0.15,IF('GİRDİ & PARAMETRELER'!D35>=5300000,D35*0.4,IF('GİRDİ & PARAMETRELER'!D35>=1500000,D35*0.35,IF('GİRDİ & PARAMETRELER'!D35>=400000,D35*0.27,IF('GİRDİ & PARAMETRELER'!D35>=190000,D35*0.2,D35*0.15))))) -> 0
C37: Damga Vergisi (‰7,59) | D37: =D30*0.00759 -> 0
C38: TOPLAM KESİNTİ | D38: =D33+D34+D36+D37 -> 0
C39: NET UBGT ÜCRETİ | D39: =D30-D38 -> 0

Sheet GENEL İCMAL
A1: İŞÇİLİK ALACAKLARI GENEL İCMAL TABLOSU – 2026
A3: BİLİRKİŞİ HESAP ÖZET SAYFASI
C5: ALACAK KALEMİ | D5: BRÜT TUTAR (TL) | E5: KESİNTİLER (TL) | F5: NET TUTAR (TL)
C6: KIDEM TAZMİNATI | D6: ='KIDEM TAZMİNATI'!D19 -> 0 | E6: ='KIDEM TAZMİNATI'!D24 -> 0 | F6: ='KIDEM TAZMİNATI'!D29 -> 0
C7: İHBAR TAZMİNATI | D7: ='İHBAR TAZMİNATI'!D20 -> 0 | E7: ='İHBAR TAZMİNATI'!D27+'İHBAR TAZMİNATI'!D30 -> 0 | F7: ='İHBAR TAZMİNATI'!D36 -> 0
C8: YILLIK İZİN ÜCRETİ | D8: ='YILLIK İZİN'!D19 -> 0 | E8: ='YILLIK İZİN'!D31 -> 0 | F8: ='YILLIK İZİN'!D36 -> 0
C9: FAZLA MESAİ ÜCRETİ | D9: ='FAZLA MESAİ & UBGT'!D12 -> 0 | E9: ='FAZLA MESAİ & UBGT'!D20 -> 0 | F9: ='FAZLA MESAİ & UBGT'!D21 -> 0
C10: UBGT ÜCRETİ | D10: ='FAZLA MESAİ & UBGT'!D30 -> 0 | E10: ='FAZLA MESAİ & UBGT'!D38 -> 0 | F10: ='FAZLA MESAİ & UBGT'!D39 -> 0
C11: GENEL TOPLAM | D11: =SUM(D6:D10) -> 0 | E11: =SUM(E6:E10) -> 0 | F11: =SUM(F6:F10) -> 0
A14: ÖZET BİLGİLER
C15: İşçi Adı / Dosya No
C16: İşe Giriş Tarihi | D16: ='GİRDİ & PARAMETRELER'!D7 -> 0
C17: İşten Çıkış Tarihi | D17: ='GİRDİ & PARAMETRELER'!D8 -> 0
C18: Hizmet Süresi | D18: ='GİRDİ & PARAMETRELER'!G7&" Yıl "&'GİRDİ & PARAMETRELER'!G8&" Ay "&'GİRDİ & PARAMETRELER'!G9&" Gün" -> Yıl Ay Gün
C19: Çıplak Brüt Ücret (TL) | D19: ='GİRDİ & PARAMETRELER'!D22 -> 0
C20: Giydirilmiş Brüt Ücret (TL) | D20: ='GİRDİ & PARAMETRELER'!D23 -> 0
C21: Kıdem Tazminatı Tavanı (TL) | D21: ='GİRDİ & PARAMETRELER'!B42 -> 0
C22: Hesaplama Tarihi | D22: =TODAY() -> 46097
A25: YASAL UYARI: Bu hesap aracı 2026 yılı yasal parametrelerine dayanmaktadır. Hesaplamalar bilirkişilik eğitimi ve ön hesaplama amacıyla hazırlanmıştır. Kesinleşmiş hukuki görüş yerine geçmez. Parametreler değiştiğinde güncellenmelidir. Kıdem Tazminatı Tavanı: 64.948,77 TL (01.01.2026–30.06.2026). Asgari Ücret: 33.030,00 TL Brüt / 28.075,50 TL Net.
